[2021-03-17 15:47:06,068] {taskinstance.py:851} INFO - Dependencies all met for <TaskInstance: PostgresOperator_dag.create_table 2021-03-17T15:47:03.756426+00:00 [queued]>
[2021-03-17 15:47:06,097] {taskinstance.py:851} INFO - Dependencies all met for <TaskInstance: PostgresOperator_dag.create_table 2021-03-17T15:47:03.756426+00:00 [queued]>
[2021-03-17 15:47:06,099] {taskinstance.py:1042} INFO - 
--------------------------------------------------------------------------------
[2021-03-17 15:47:06,100] {taskinstance.py:1043} INFO - Starting attempt 1 of 1
[2021-03-17 15:47:06,101] {taskinstance.py:1044} INFO - 
--------------------------------------------------------------------------------
[2021-03-17 15:47:06,112] {taskinstance.py:1063} INFO - Executing <Task(PostgresOperator): create_table> on 2021-03-17T15:47:03.756426+00:00
[2021-03-17 15:47:06,118] {standard_task_runner.py:52} INFO - Started process 44 to run task
[2021-03-17 15:47:06,124] {standard_task_runner.py:76} INFO - Running: ['airflow', 'tasks', 'run', 'PostgresOperator_dag', 'create_table', '2021-03-17T15:47:03.756426+00:00', '--job-id', '5', '--pool', 'default_pool', '--raw', '--subdir', 'DAGS_FOLDER/first.py', '--cfg-path', '/tmp/tmp8l7x49i3', '--error-file', '/tmp/tmpdggvo04v']
[2021-03-17 15:47:06,127] {standard_task_runner.py:77} INFO - Job 5: Subtask create_table
[2021-03-17 15:47:06,210] {logging_mixin.py:104} INFO - Running <TaskInstance: PostgresOperator_dag.create_table 2021-03-17T15:47:03.756426+00:00 [running]> on host c065581206d5
[2021-03-17 15:47:06,282] {taskinstance.py:1257} INFO - Exporting the following env vars:
AIRFLOW_CTX_DAG_OWNER=airflow
AIRFLOW_CTX_DAG_ID=PostgresOperator_dag
AIRFLOW_CTX_TASK_ID=create_table
AIRFLOW_CTX_EXECUTION_DATE=2021-03-17T15:47:03.756426+00:00
AIRFLOW_CTX_DAG_RUN_ID=manual__2021-03-17T15:47:03.756426+00:00
[2021-03-17 15:47:06,285] {postgres.py:69} INFO - Executing: CREATE TABLE IF NOT EXISTS user_table(
            id integer NOT NULL, email VARCHAR, active BOOLEAN
            );
[2021-03-17 15:47:06,339] {taskinstance.py:1455} ERROR - The conn_id `postgresql` isn't defined
Traceback (most recent call last):
  File "/home/airflow/.local/lib/python3.6/site-packages/airflow/models/taskinstance.py", line 1112, in _run_raw_task
    self._prepare_and_execute_task_with_callbacks(context, task)
  File "/home/airflow/.local/lib/python3.6/site-packages/airflow/models/taskinstance.py", line 1285, in _prepare_and_execute_task_with_callbacks
    result = self._execute_task(context, task_copy)
  File "/home/airflow/.local/lib/python3.6/site-packages/airflow/models/taskinstance.py", line 1315, in _execute_task
    result = task_copy.execute(context=context)
  File "/home/airflow/.local/lib/python3.6/site-packages/airflow/providers/postgres/operators/postgres.py", line 71, in execute
    self.hook.run(self.sql, self.autocommit, parameters=self.parameters)
  File "/home/airflow/.local/lib/python3.6/site-packages/airflow/hooks/dbapi.py", line 173, in run
    with closing(self.get_conn()) as conn:
  File "/home/airflow/.local/lib/python3.6/site-packages/airflow/providers/postgres/hooks/postgres.py", line 83, in get_conn
    conn = self.connection or self.get_connection(conn_id)
  File "/home/airflow/.local/lib/python3.6/site-packages/airflow/hooks/base.py", line 63, in get_connection
    conn = Connection.get_connection_from_secrets(conn_id)
  File "/home/airflow/.local/lib/python3.6/site-packages/airflow/models/connection.py", line 354, in get_connection_from_secrets
    raise AirflowNotFoundException(f"The conn_id `{conn_id}` isn't defined")
airflow.exceptions.AirflowNotFoundException: The conn_id `postgresql` isn't defined
[2021-03-17 15:47:06,346] {taskinstance.py:1503} INFO - Marking task as FAILED. dag_id=PostgresOperator_dag, task_id=create_table, execution_date=20210317T154703, start_date=20210317T154706, end_date=20210317T154706
[2021-03-17 15:47:06,390] {local_task_job.py:146} INFO - Task exited with return code 1
