[2021-03-17 16:08:48,794] {taskinstance.py:851} INFO - Dependencies all met for <TaskInstance: PostgresOperator_dag.insert_row 2021-03-17T16:08:47.112795+00:00 [queued]>
[2021-03-17 16:08:48,822] {taskinstance.py:851} INFO - Dependencies all met for <TaskInstance: PostgresOperator_dag.insert_row 2021-03-17T16:08:47.112795+00:00 [queued]>
[2021-03-17 16:08:48,823] {taskinstance.py:1042} INFO - 
--------------------------------------------------------------------------------
[2021-03-17 16:08:48,824] {taskinstance.py:1043} INFO - Starting attempt 1 of 1
[2021-03-17 16:08:48,825] {taskinstance.py:1044} INFO - 
--------------------------------------------------------------------------------
[2021-03-17 16:08:48,837] {taskinstance.py:1063} INFO - Executing <Task(PostgresOperator): insert_row> on 2021-03-17T16:08:47.112795+00:00
[2021-03-17 16:08:48,843] {standard_task_runner.py:52} INFO - Started process 43 to run task
[2021-03-17 16:08:48,851] {standard_task_runner.py:76} INFO - Running: ['airflow', 'tasks', 'run', 'PostgresOperator_dag', 'insert_row', '2021-03-17T16:08:47.112795+00:00', '--job-id', '14', '--pool', 'default_pool', '--raw', '--subdir', 'DAGS_FOLDER/first.py', '--cfg-path', '/tmp/tmpk1087xqw', '--error-file', '/tmp/tmplwe3m4no']
[2021-03-17 16:08:48,853] {standard_task_runner.py:77} INFO - Job 14: Subtask insert_row
[2021-03-17 16:08:48,921] {logging_mixin.py:104} INFO - Running <TaskInstance: PostgresOperator_dag.insert_row 2021-03-17T16:08:47.112795+00:00 [running]> on host c065581206d5
[2021-03-17 16:08:48,984] {taskinstance.py:1257} INFO - Exporting the following env vars:
AIRFLOW_CTX_DAG_OWNER=airflow
AIRFLOW_CTX_DAG_ID=PostgresOperator_dag
AIRFLOW_CTX_TASK_ID=insert_row
AIRFLOW_CTX_EXECUTION_DATE=2021-03-17T16:08:47.112795+00:00
AIRFLOW_CTX_DAG_RUN_ID=manual__2021-03-17T16:08:47.112795+00:00
[2021-03-17 16:08:48,986] {postgres.py:69} INFO - Executing: INSERT INTO user_table VALUES(%s, %s, %s)
[2021-03-17 16:08:49,009] {base.py:74} INFO - Using connection to: id: postgresql. Host: db, Port: 5432, Schema: airflow, Login: postgres, Password: XXXXXXXX, extra: None
[2021-03-17 16:08:49,018] {dbapi.py:180} INFO - Running statement: INSERT INTO user_table VALUES(%s, %s, %s), parameters: (73161314, 'felix_airflow@works.com', True)
[2021-03-17 16:08:49,021] {taskinstance.py:1455} ERROR - relation "user_table" does not exist
LINE 1: INSERT INTO user_table VALUES(73161314, 'felix_airflow@works...
                    ^
Traceback (most recent call last):
  File "/home/airflow/.local/lib/python3.6/site-packages/airflow/models/taskinstance.py", line 1112, in _run_raw_task
    self._prepare_and_execute_task_with_callbacks(context, task)
  File "/home/airflow/.local/lib/python3.6/site-packages/airflow/models/taskinstance.py", line 1285, in _prepare_and_execute_task_with_callbacks
    result = self._execute_task(context, task_copy)
  File "/home/airflow/.local/lib/python3.6/site-packages/airflow/models/taskinstance.py", line 1315, in _execute_task
    result = task_copy.execute(context=context)
  File "/home/airflow/.local/lib/python3.6/site-packages/airflow/providers/postgres/operators/postgres.py", line 71, in execute
    self.hook.run(self.sql, self.autocommit, parameters=self.parameters)
  File "/home/airflow/.local/lib/python3.6/site-packages/airflow/hooks/dbapi.py", line 182, in run
    cur.execute(sql_statement, parameters)
psycopg2.errors.UndefinedTable: relation "user_table" does not exist
LINE 1: INSERT INTO user_table VALUES(73161314, 'felix_airflow@works...
                    ^

[2021-03-17 16:08:49,025] {taskinstance.py:1503} INFO - Marking task as FAILED. dag_id=PostgresOperator_dag, task_id=insert_row, execution_date=20210317T160847, start_date=20210317T160848, end_date=20210317T160849
[2021-03-17 16:08:49,069] {local_task_job.py:146} INFO - Task exited with return code 1
